<?xml version="1.0"?>
<robot name="panther" xmlns:xacro="http://ros.org/wiki/xacro">

	<!-- Link setup -->
	<link name="fr_wheel_link">
		<inertial>
			<origin xyz="0 0 0" rpy="1.5708 0 0"/>
			<mass value="6"/>
			<inertia ixx="0.047" ixy="0" ixz="0" iyy="0.047" iyz="0" izz="0.078" />
		</inertial>

		<visual>
			<origin xyz="0 0 0" rpy="1.5708 0.0 0.0"/>
			<geometry>
				<cylinder radius="0.15" length="0.108"/>
			</geometry>
			<material name="wheel">
				<color rgba="0 0 0 1.0" />
			</material>
		</visual>

		<collision>
			<origin xyz="0 0 0" rpy="1.5708 0.0 0.0"/>
			<geometry>
				<cylinder radius="0.15" length="0.108"/>
			</geometry>
		</collision>
	</link>

	<link name="mr_wheel_link">
		<!--inertial>
			<origin xyz="0 0 0" rpy="1.5708 0 0"/>
			<mass value="6"/>
			<inertia ixx="0.11" ixy="0" ixz="0" iyy="0.11" iyz="0" izz="0.15" />
		</inertial-->

		<visual>
			<origin xyz="0.0 0 0" rpy="1.5708 0.0 0.0"/>
			<geometry> 
				<cylinder radius="0.15" length="0.108"/>
			</geometry>
			<material name="wheel">
				<color rgba="0 0 0 1.0" />
			</material>
		</visual>

		<!--collision>
			<origin xyz="0.0 0 0.054" />
			<geometry>
				<cylinder radius="0.15" length="0.108"/>
			</geometry>
		</collision-->
	</link>

	<link name="rr_wheel_link">
		<inertial>
			<origin xyz="0 0 0" rpy="1.5708 0 0"/>
			<mass value="6"/>
			<inertia ixx="0.047" ixy="0" ixz="0" iyy="0.047" iyz="0" izz="0.078" />
		</inertial>

		<visual>
			<origin xyz="0 0 0" rpy="1.5708 0.0 0.0"/>
			<geometry>
				<cylinder radius="0.15" length="0.108"/>
			</geometry>
			<material name="wheel">
				<color rgba="0 0 0 1.0" />
			</material>
		</visual>

		<collision>
			<origin xyz="0 0 0" rpy="1.5708 0.0 0.0"/>
			<geometry>
				<cylinder radius="0.15" length="0.108"/>
			</geometry>
		</collision>
	</link>

	<link name="fl_wheel_link">
		<inertial>
			<origin xyz="0 0 0" rpy="1.5708 0 0"/>
			<mass value="6"/>
			<inertia ixx="0.047" ixy="0" ixz="0" iyy="0.047" iyz="0" izz="0.078" />
		</inertial>

		<visual>
			<origin xyz="0 0 0" rpy="-1.5708 0.0 0.0"/>
			<geometry>
				<cylinder radius="0.15" length="0.108"/>
			</geometry>
			<material name="wheel">
				<color rgba="0 0 0 1.0" />
			</material>
		</visual>

		<collision>
			<origin xyz="0 0 0" rpy="-1.5708 0.0 0.0"/>
			<geometry>
				<cylinder radius="0.15" length="0.108"/>
			</geometry>
		</collision>
	</link>

	<link name="ml_wheel_link">
		<!--inertial>
			<origin xyz="0 0 0" rpy="1.5708 0 0" />
			<mass value="6"/>
			<inertia ixx="0.11" ixy="0" ixz="0" iyy="0.11" iyz="0" izz="0.15" />
		</inertial-->

		<visual>
			<origin xyz="0 0 0" rpy="-1.5708 0.0 0.0"/>
			<geometry>
				<cylinder radius="0.15" length="0.108"/>
			</geometry>
			<material name="wheel">
				<color rgba="0 0 0 1.0" />
			</material>
		</visual>

		<!--collision>
			<origin xyz="0 0 0.054"/>
			<geometry>
				<cylinder radius="0.15" length="0.108"/>
			</geometry>
		</collision-->
	</link>

	<link name="rl_wheel_link"> 
		<inertial>
			<origin xyz="0 0 0" rpy="1.5708 0 0"/>
			<mass value="6"/>
			<inertia ixx="0.047" ixy="0" ixz="0" iyy="0.047" iyz="0" izz="0.078" />
		</inertial>

		<visual>
			<origin xyz="0 0 0" rpy="-1.5708 0.0 0.0"/>
			<geometry>
				<cylinder radius="0.15" length="0.108"/>
			</geometry>
			<material name="wheel">
				<color rgba="0 0 0 1.0" />
			</material>
		</visual>

		<collision>
			<origin xyz="0 0 0" rpy="-1.5708 0.0 0.0"/>
			<geometry>
				<cylinder radius="0.15" length="0.108"/>
			</geometry>
		</collision>
	</link>

	<link name="base_link">
		<inertial>
			<origin xyz="0 0 0.293" rpy="0 0 0"/>
			<mass value="55"/>
			<inertia ixx="2.743" ixy="0" ixz="0" iyy="5.705" iyz="0" izz="6.801" />
			<!--nertia ixx="7.315" ixy="0" ixz="0" iyy="10.276" iyz="0" izz="6.801" /-->
		</inertial>

		<visual>
			<origin xyz="0 0 0.293"/>
			<geometry>
				<box size = "0.914 0.53975 0.312"/>
			</geometry>
			<material name="hk1500">
				<color rgba="0.57 0.58 0.57 1.0" /> 
			</material>
		</visual>

		<collision>
			<origin xyz="0 0 0.293"/>
			<geometry> 
				<box size = "0.914 0.53975 0.312"/>
			</geometry>
		</collision> 
	</link>
	<link name="base_footprint"/>
	
	
	<!-- Joint defines -->
    <joint name="base_joint" type="fixed">
        <origin xyz="0 0 0.293" rpy="0 0 0"/>
        <parent link="base_footprint"/>
        <child link="base_link"/>
    </joint>
	<joint name="fr_wheel_joint" type="continuous">
		<parent link="base_link"/>
		<child link="fr_wheel_link"/>
		<axis xyz="0 1 0"/>
		<origin xyz="0.356108 -0.323875 0.137" />
	</joint>
	<joint name="fl_wheel_joint" type="continuous">
		<parent link="base_link"/>
		<child link="fl_wheel_link"/>
		<axis xyz="0 1 0"/>
		<origin xyz="0.356108 0.323875 0.137" />
	</joint>

	<joint name="mr_wheel_joint" type="fixed">
		<parent link="base_link"/>
		<child link="mr_wheel_link"/>
		<axis xyz="0 1 0"/>
		<origin xyz="0.0 -0.323875 0.137" />
	</joint>

	<joint name="ml_wheel_joint" type="fixed">
		<parent link="base_link"/>
		<child link="ml_wheel_link"/>
		<axis xyz="0 1 0"/>
		<origin xyz="0.0 0.323875 0.137" />
	</joint>

	<joint name="rr_wheel_joint" type="continuous">
		<parent link="base_link"/>
		<child link="rr_wheel_link"/>
		<axis xyz="0 1 0"/>
		<origin xyz="-0.356108 -0.323875 0.137" />
	</joint>
	<joint name="rl_wheel_joint" type="continuous">
		<parent link="base_link"/>
		<child link="rl_wheel_link"/>
		<axis xyz="0 1 0"/>
		<origin xyz="-0.356108 0.323875 0.137" />
	</joint>
	
	<!-- Lidar -->
	<link name="hokuyo_link"> 
    	<visual>
      		<origin xyz="0 0 0.003"/>
      		<geometry>
        		<box size="0.079 0.05 0.006"/>
      		</geometry>
      		<material name="support">
        		<color rgba="0.5 0.5 0.5 1.0"/>
      		</material>
    	</visual>
    	<visual>
      		<origin xyz="0 0 0.041"/>
      		<geometry>
        		<box size="0.05 0.05 0.07"/>
      		</geometry>
      		<material name="lidar">
        		<color rgba="1.0 0.0 0.0 0.7"/>
      		</material>
    	</visual>
    	<collision>
      		<origin xyz="0 0 0.003"/>
      		<geometry>
        		<box size="0.079 0.05 0.006"/>
      		</geometry>
    	</collision>
    	<collision>
      		<origin xyz="0 0 0.041"/>
      		<geometry>
        		<box size="0.05 0.05 0.07"/>
      		</geometry>
    	</collision>
  	</link>

  	<joint name="hokuyo_joint" type="fixed">
    		<origin xyz="0.356108 0 0.449"/>
    		<parent link="base_link"/>
    		<child link="hokuyo_link"/>
  	</joint>

  	<link name="laser_frame"/>

  	<joint name="laser_joint" type="fixed">
    		<origin xyz="0 0 0.04"/> <!-- something is weird here, was xyz = 0 0 0.513-->
    		<parent link="hokuyo_link"/>
    		<child link="laser_frame"/>
  	</joint>
  	
  	<!-- IMU -->
	<link name="imu_link"> 
    	<visual>
      		<origin xyz="0 0 0.003"/>
      		<geometry>
        		<box size="0.079 0.05 0.006"/>
      		</geometry>
      		<material name="imu">
        		<color rgba="0.5 0.5 0 1.0"/>
      		</material>
    	</visual>
		<collision>
      		<origin xyz="0 0 0.003"/>
      		<geometry>
        		<box size="0.079 0.05 0.006"/>
      		</geometry>
    	</collision>
	</link>

	<joint name="imu_joint" type="fixed">
    		<origin xyz="0 0 0.449"/>
    		<parent link="base_link"/>
    		<child link="imu_link"/>
  	</joint>
	
  	
  <!-- Gazebo -->
  
  <!-- ros_control plugin 
  <gazebo>
    <plugin name="gazebo_ros_control" filename="libgazebo_ros_control.so">
      <robotNamespace></robotNamespace>
      <robotSimType>gazebo_ros_control/DefaultRobotHWSim</robotSimType>
    </plugin>
  </gazebo>-->
  

  <!-- Base -->
  <gazebo reference="base_link">
    <material>Gazebo/Grey</material>
  </gazebo>

  <!-- Front Right Wheel -->
  <gazebo reference="fr_wheel_link">
    <collision> 
    <surface>
      <friction>
        <ode>
          <mu>0.5</mu>
          <mu2>1</mu2>
		  <slip1> 0.0016 </slip1>
		  <slip2> 0 </slip2>
		  <fdir1> 0 0 1 </fdir1>
        </ode>
      </friction>
    </surface>
  </collision>
  </gazebo>

  <!-- Front Left Wheel -->
  <gazebo reference="fl_wheel_link">
    <collision> 
    <surface>
      <friction>
        <ode>
          <mu>0.5</mu>
          <mu2>1</mu2>
		  <slip1> 0.0016 </slip1>
		  <slip2> 0 </slip2>
		  <fdir1> 0 0 1 </fdir1>
        </ode>
      </friction>
    </surface>
  </collision>
  </gazebo>
  
  <!-- Middle Right Wheel -->
  <!--gazebo reference="mr_wheel_link">
    <collision> 
    <surface>
      <friction>
        <ode>
          <mu>0.5</mu>
          <mu2>0.5</mu2>
        </ode>
      </friction>
    </surface>
  </collision>
  </gazebo-->

<!-- Middle Left Wheel >
  <gazebo reference="ml_wheel_link">
    <collision> 
    <surface>
      <friction>
        <ode>
          <mu>0.5</mu>
          <mu2>0.5</mu2>
        </ode>
      </friction>
    </surface>
  </collision>
  </gazebo-->

<!-- Rear Right Wheel -->
  <gazebo reference="rr_wheel_link">
   <collision> 
    <surface>
      <friction>
        <ode>
          <mu>0.5</mu>
          <mu2>1</mu2>
		  <slip1> 0.0016 </slip1>
		  <slip2> 0 </slip2>
		  <fdir1> 0 0 1 </fdir1>
        </ode>
      </friction>
    </surface>
  </collision>
  </gazebo>

<!-- Rear Left Wheel -->
  <gazebo reference="rl_wheel_link">
   <collision> 
    <surface>
      <friction>
        <ode>
          <mu>0.5</mu>
          <mu2>1</mu2>
		  <slip1> 0.0016 </slip1>
		  <slip2> 0 </slip2>
		  <fdir1> 0 0 1 </fdir1>
        </ode>
      </friction>
    </surface>
  </collision>
  </gazebo>

  <!-- camera_link 
  <gazebo reference="camera_link">
    <mu1>0.2</mu1>
    <mu2>0.2</mu2>
    <material>Gazebo/Red</material>
  </gazebo>-->

<!-- Skid Steer Plugin -->
 <gazebo>
  <plugin name="skid_steer_drive_controller" filename="libgazebo_ros_skid_steer_drive.so">
    <updateRate>200.0</updateRate>
    <robotNamespace></robotNamespace>
    <leftFrontJoint>fl_wheel_joint</leftFrontJoint>
    <rightFrontJoint>fr_wheel_joint</rightFrontJoint>
    <leftRearJoint>rl_wheel_joint</leftRearJoint>
    <rightRearJoint>rr_wheel_joint</rightRearJoint>
    <wheelSeparation>0.4</wheelSeparation>
    <wheelDiameter>0.215</wheelDiameter>
    <robotBaseFrame>base_footprint</robotBaseFrame>
    <torque>100</torque>
    <commandTopic>cmd_vel</commandTopic>
    <odometryFrame>odom</odometryFrame>
    <broadcastTF>True</broadcastTF>
  </plugin>
</gazebo>

  <!-- Lidar -->
  <gazebo reference="laser_frame">
    <sensor type="ray" name="head_hokuyo_sensor">
      <pose>0 0 0 0 0 0</pose>
      <visualize>false</visualize>
      <update_rate>100</update_rate>
      <ray>
        <scan>
          <horizontal>
            <samples>1080</samples>
            <resolution>1</resolution>
            <min_angle>-2.35619</min_angle>
            <max_angle>2.35619</max_angle>
          </horizontal>
        </scan>
        <range>
          <min>0.10</min>
          <max>30.0</max>
          <resolution>0.01</resolution>
        </range>
        <noise>
          <type>gaussian</type>
          <!-- Noise parameters based on published spec for Hokuyo laser
               achieving "+-30mm" accuracy at range < 10m.  A mean of 0.0m and
               stddev of 0.01m will put 99.7% of samples within 0.03m of the true
               reading. -->
          <mean>0.0</mean>
          <stddev>0.01</stddev>
        </noise>
      </ray>
      <plugin name="gazebo_ros_head_hokuyo_controller" filename="libgazebo_ros_laser.so">
        <topicName>/scan</topicName>
        <frameName>hokuyo_link</frameName>
      </plugin>
    </sensor>
  </gazebo>

	<!-- IMU -->
  <gazebo reference="imu_link">
    <gravity>true</gravity>
    <sensor name="imu_sensor" type="imu">
      <always_on>true</always_on>
      <update_rate>100</update_rate>
      <visualize>true</visualize>
      <topic>/imu/data_raw</topic>
      <plugin filename="libgazebo_ros_imu_sensor.so" name="imu_plugin">
        <topicName>/imu/data_raw</topicName>
        <bodyName>imu_link</bodyName>
        <updateRateHZ>10.0</updateRateHZ>
        <gaussianNoise>0.0</gaussianNoise>
        <xyzOffset>0 0 0</xyzOffset>
        <rpyOffset>0 0 0</rpyOffset>
        <frameName>imu_link</frameName>
        <initialOrientationAsReference>false</initialOrientationAsReference>
      </plugin>
      <pose>0 0 0 0 0 0</pose>
    </sensor>
  </gazebo>


</robot>
