<sdf version='1.7'>
  <model name='panther'>
    <link name='base_footprint'>
      <inertial>
        <pose>0 0 0.586 0 -0 0</pose>
        <mass>55</mass>
        <inertia>
          <ixx>2.743</ixx>
          <ixy>0</ixy>
          <ixz>0</ixz>
          <iyy>5.705</iyy>
          <iyz>0</iyz>
          <izz>6.801</izz>
        </inertia>
      </inertial>
      <collision name='base_footprint_fixed_joint_lump__base_link_collision'>
        <pose>0 0 0.586 0 -0 0</pose>
        <geometry>
          <box>
            <size>0.914 0.53975 0.312</size>
          </box>
        </geometry>
        <surface>
          <contact>
            <ode/>
          </contact>
          <friction>
            <ode/>
          </friction>
        </surface>
      </collision>
      <collision name='base_footprint_fixed_joint_lump__hokuyo_link_collision_1'>
        <pose>0.356108 0 0.745 0 -0 0</pose>
        <geometry>
          <box>
            <size>0.079 0.05 0.006</size>
          </box>
        </geometry>
      </collision>
      <collision name='base_footprint_fixed_joint_lump__hokuyo_link_collision_2'>
        <pose>0.356108 0 0.783 0 -0 0</pose>
        <geometry>
          <box>
            <size>0.05 0.05 0.07</size>
          </box>
        </geometry>
      </collision>
      <collision name='base_footprint_fixed_joint_lump__imu_link_collision_3'>
        <pose>0 0 0.745 0 -0 0</pose>
        <geometry>
          <box>
            <size>0.079 0.05 0.006</size>
          </box>
        </geometry>
        <surface>
          <contact>
            <ode/>
          </contact>
          <friction>
            <ode/>
          </friction>
        </surface>
      </collision>
      <visual name='base_footprint_fixed_joint_lump__base_link_visual'>
        <pose>0 0 0.586 0 -0 0</pose>
        <geometry>
          <box>
            <size>0.914 0.53975 0.312</size>
          </box>
        </geometry>
        <material>
          <script>
            <name>Gazebo/Grey</name>
            <uri>file://media/materials/scripts/gazebo.material</uri>
          </script>
        </material>
      </visual>
      <visual name='base_footprint_fixed_joint_lump__hokuyo_link_visual_1'>
        <pose>0.356108 0 0.745 0 -0 0</pose>
        <geometry>
          <box>
            <size>0.079 0.05 0.006</size>
          </box>
        </geometry>
      </visual>
      <visual name='base_footprint_fixed_joint_lump__hokuyo_link_visual_2'>
        <pose>0.356108 0 0.783 0 -0 0</pose>
        <geometry>
          <box>
            <size>0.05 0.05 0.07</size>
          </box>
        </geometry>
      </visual>
      <visual name='base_footprint_fixed_joint_lump__imu_link_visual_3'>
        <pose>0 0 0.745 0 -0 0</pose>
        <geometry>
          <box>
            <size>0.079 0.05 0.006</size>
          </box>
        </geometry>
      </visual>
      <visual name='base_footprint_fixed_joint_lump__ml_wheel_link_visual_4'>
        <pose>0 0.323875 0.43 -1.5708 0 0</pose>
        <geometry>
          <cylinder>
            <length>0.108</length>
            <radius>0.15</radius>
          </cylinder>
        </geometry>
      </visual>
      <visual name='base_footprint_fixed_joint_lump__mr_wheel_link_visual_5'>
        <pose>0 -0.323875 0.43 1.5708 -0 0</pose>
        <geometry>
          <cylinder>
            <length>0.108</length>
            <radius>0.15</radius>
          </cylinder>
        </geometry>
      </visual>
      <sensor name='head_hokuyo_sensor' type='ray'>
        <visualize>1</visualize>
        <update_rate>100</update_rate>
        <ray>
          <scan>
            <horizontal>
              <samples>1080</samples>
              <resolution>1</resolution>
              <min_angle>-2.35619</min_angle>
              <max_angle>2.35619</max_angle>
            </horizontal>
          </scan>
          <range>
            <min>0.1</min>
            <max>30</max>
            <resolution>0.01</resolution>
          </range>
          <noise>
            <type>gaussian</type>
            <mean>0</mean>
            <stddev>0.01</stddev>
          </noise>
        </ray>
        <plugin name='gazebo_ros_head_hokuyo_controller' filename='libgazebo_ros_laser.so'>
          <topicName>/scan</topicName>
          <frameName>hokuyo_link</frameName>
        </plugin>
        <pose>0.356108 0 0.782 0 -0 0</pose>
      </sensor>
      <gravity>1</gravity>
      <sensor name='imu_sensor' type='imu'>
        <always_on>1</always_on>
        <update_rate>100</update_rate>
        <visualize>1</visualize>
        <topic>/imu/data_raw</topic>
        <plugin name='imu_plugin' filename='libgazebo_ros_imu_sensor.so'>
          <topicName>/imu/data_raw</topicName>
          <bodyName>imu_link</bodyName>
          <updateRateHZ>10.0</updateRateHZ>
          <gaussianNoise>0.0</gaussianNoise>
          <xyzOffset>0 0 0</xyzOffset>
          <rpyOffset>0 0 0</rpyOffset>
          <frameName>imu_link</frameName>
          <initialOrientationAsReference>0</initialOrientationAsReference>
        </plugin>
        <pose>0 0 0.742 0 -0 0</pose>
      </sensor>
    </link>
    <joint name='fl_wheel_joint' type='revolute'>
      <pose relative_to='base_footprint'>0.356108 0.323875 0.43 0 -0 0</pose>
      <parent>base_footprint</parent>
      <child>fl_wheel_link</child>
      <axis>
        <xyz>0 1 0</xyz>
        <limit>
          <lower>-1e+16</lower>
          <upper>1e+16</upper>
        </limit>
        <dynamics>
          <spring_reference>0</spring_reference>
          <spring_stiffness>0</spring_stiffness>
        </dynamics>
      </axis>
    </joint>
    <link name='fl_wheel_link'>
      <pose relative_to='fl_wheel_joint'>0 0 0 0 -0 0</pose>
      <inertial>
        <pose>0 0 0 1.5708 -0 0</pose>
        <mass>6</mass>
        <inertia>
          <ixx>0.047</ixx>
          <ixy>0</ixy>
          <ixz>0</ixz>
          <iyy>0.047</iyy>
          <iyz>0</iyz>
          <izz>0.078</izz>
        </inertia>
      </inertial>
      <collision name='fl_wheel_link_collision'>
        <pose>0 0 0 -1.5708 0 0</pose>
        <geometry>
          <cylinder>
            <length>0.108</length>
            <radius>0.15</radius>
          </cylinder>
        </geometry>
        <surface>
          <friction>
            <ode>
              <mu>0.5</mu>
              <mu2>1</mu2>
              <slip1>0.0016</slip1>
              <slip2>0</slip2>
              <fdir1>0 0 1</fdir1>
            </ode>
          </friction>
          <contact>
            <ode/>
          </contact>
        </surface>
      </collision>
      <visual name='fl_wheel_link_visual'>
        <pose>0 0 0 -1.5708 0 0</pose>
        <geometry>
          <cylinder>
            <length>0.108</length>
            <radius>0.15</radius>
          </cylinder>
        </geometry>
      </visual>
    </link>
    <joint name='fr_wheel_joint' type='revolute'>
      <pose relative_to='base_footprint'>0.356108 -0.323875 0.43 0 -0 0</pose>
      <parent>base_footprint</parent>
      <child>fr_wheel_link</child>
      <axis>
        <xyz>0 1 0</xyz>
        <limit>
          <lower>-1e+16</lower>
          <upper>1e+16</upper>
        </limit>
        <dynamics>
          <spring_reference>0</spring_reference>
          <spring_stiffness>0</spring_stiffness>
        </dynamics>
      </axis>
    </joint>
    <link name='fr_wheel_link'>
      <pose relative_to='fr_wheel_joint'>0 0 0 0 -0 0</pose>
      <inertial>
        <pose>0 0 0 1.5708 -0 0</pose>
        <mass>6</mass>
        <inertia>
          <ixx>0.047</ixx>
          <ixy>0</ixy>
          <ixz>0</ixz>
          <iyy>0.047</iyy>
          <iyz>0</iyz>
          <izz>0.078</izz>
        </inertia>
      </inertial>
      <collision name='fr_wheel_link_collision'>
        <pose>0 0 0 1.5708 -0 0</pose>
        <geometry>
          <cylinder>
            <length>0.108</length>
            <radius>0.15</radius>
          </cylinder>
        </geometry>
        <surface>
          <friction>
            <ode>
              <mu>0.5</mu>
              <mu2>1</mu2>
              <slip1>0.0016</slip1>
              <slip2>0</slip2>
              <fdir1>0 0 1</fdir1>
            </ode>
          </friction>
          <contact>
            <ode/>
          </contact>
        </surface>
      </collision>
      <visual name='fr_wheel_link_visual'>
        <pose>0 0 0 1.5708 -0 0</pose>
        <geometry>
          <cylinder>
            <length>0.108</length>
            <radius>0.15</radius>
          </cylinder>
        </geometry>
      </visual>
    </link>
    <joint name='rl_wheel_joint' type='revolute'>
      <pose relative_to='base_footprint'>-0.356108 0.323875 0.43 0 -0 0</pose>
      <parent>base_footprint</parent>
      <child>rl_wheel_link</child>
      <axis>
        <xyz>0 1 0</xyz>
        <limit>
          <lower>-1e+16</lower>
          <upper>1e+16</upper>
        </limit>
        <dynamics>
          <spring_reference>0</spring_reference>
          <spring_stiffness>0</spring_stiffness>
        </dynamics>
      </axis>
    </joint>
    <link name='rl_wheel_link'>
      <pose relative_to='rl_wheel_joint'>0 0 0 0 -0 0</pose>
      <inertial>
        <pose>0 0 0 1.5708 -0 0</pose>
        <mass>6</mass>
        <inertia>
          <ixx>0.047</ixx>
          <ixy>0</ixy>
          <ixz>0</ixz>
          <iyy>0.047</iyy>
          <iyz>0</iyz>
          <izz>0.078</izz>
        </inertia>
      </inertial>
      <collision name='rl_wheel_link_collision'>
        <pose>0 0 0 -1.5708 0 0</pose>
        <geometry>
          <cylinder>
            <length>0.108</length>
            <radius>0.15</radius>
          </cylinder>
        </geometry>
        <surface>
          <friction>
            <ode>
              <mu>0.5</mu>
              <mu2>1</mu2>
              <slip1>0.0016</slip1>
              <slip2>0</slip2>
              <fdir1>0 0 1</fdir1>
            </ode>
          </friction>
          <contact>
            <ode/>
          </contact>
        </surface>
      </collision>
      <visual name='rl_wheel_link_visual'>
        <pose>0 0 0 -1.5708 0 0</pose>
        <geometry>
          <cylinder>
            <length>0.108</length>
            <radius>0.15</radius>
          </cylinder>
        </geometry>
      </visual>
    </link>
    <joint name='rr_wheel_joint' type='revolute'>
      <pose relative_to='base_footprint'>-0.356108 -0.323875 0.43 0 -0 0</pose>
      <parent>base_footprint</parent>
      <child>rr_wheel_link</child>
      <axis>
        <xyz>0 1 0</xyz>
        <limit>
          <lower>-1e+16</lower>
          <upper>1e+16</upper>
        </limit>
        <dynamics>
          <spring_reference>0</spring_reference>
          <spring_stiffness>0</spring_stiffness>
        </dynamics>
      </axis>
    </joint>
    <link name='rr_wheel_link'>
      <pose relative_to='rr_wheel_joint'>0 0 0 0 -0 0</pose>
      <inertial>
        <pose>0 0 0 1.5708 -0 0</pose>
        <mass>6</mass>
        <inertia>
          <ixx>0.047</ixx>
          <ixy>0</ixy>
          <ixz>0</ixz>
          <iyy>0.047</iyy>
          <iyz>0</iyz>
          <izz>0.078</izz>
        </inertia>
      </inertial>
      <collision name='rr_wheel_link_collision'>
        <pose>0 0 0 1.5708 -0 0</pose>
        <geometry>
          <cylinder>
            <length>0.108</length>
            <radius>0.15</radius>
          </cylinder>
        </geometry>
        <surface>
          <friction>
            <ode>
              <mu>0.5</mu>
              <mu2>1</mu2>
              <slip1>0.0016</slip1>
              <slip2>0</slip2>
              <fdir1>0 0 1</fdir1>
            </ode>
          </friction>
          <contact>
            <ode/>
          </contact>
        </surface>
      </collision>
      <visual name='rr_wheel_link_visual'>
        <pose>0 0 0 1.5708 -0 0</pose>
        <geometry>
          <cylinder>
            <length>0.108</length>
            <radius>0.15</radius>
          </cylinder>
        </geometry>
      </visual>
    </link>
    <plugin name='skid_steer_drive_controller' filename='libgazebo_ros_skid_steer_drive.so'>
      <updateRate>200.0</updateRate>
      <robotNamespace/>
      <leftFrontJoint>fl_wheel_joint</leftFrontJoint>
      <rightFrontJoint>fr_wheel_joint</rightFrontJoint>
      <leftRearJoint>rl_wheel_joint</leftRearJoint>
      <rightRearJoint>rr_wheel_joint</rightRearJoint>
      <wheelSeparation>0.4</wheelSeparation>
      <wheelDiameter>0.215</wheelDiameter>
      <robotBaseFrame>base_footprint</robotBaseFrame>
      <torque>100</torque>
      <commandTopic>cmd_vel</commandTopic>
      <odometryFrame>odom</odometryFrame>
      <broadcastTF>1</broadcastTF>
    </plugin>
    <frame name='laser_joint' attached_to='hokuyo_link'>
      <pose>0 0 0.04 0 -0 0</pose>
    </frame>
    <frame name='laser_frame' attached_to='laser_joint'/>
    <frame name='hokuyo_joint' attached_to='base_link'>
      <pose>0.356108 0 0.449 0 -0 0</pose>
    </frame>
    <frame name='hokuyo_link' attached_to='hokuyo_joint'/>
    <frame name='imu_joint' attached_to='base_link'>
      <pose>0 0 0.449 0 -0 0</pose>
    </frame>
    <frame name='imu_link' attached_to='imu_joint'/>
    <frame name='ml_wheel_joint' attached_to='base_link'>
      <pose>0 0.323875 0.137 0 -0 0</pose>
    </frame>
    <frame name='ml_wheel_link' attached_to='ml_wheel_joint'/>
    <frame name='mr_wheel_joint' attached_to='base_link'>
      <pose>0 -0.323875 0.137 0 -0 0</pose>
    </frame>
    <frame name='mr_wheel_link' attached_to='mr_wheel_joint'/>
    <frame name='base_joint' attached_to='base_footprint'>
      <pose>0 0 0.293 0 -0 0</pose>
    </frame>
    <frame name='base_link' attached_to='base_joint'/>
  </model>
</sdf>
